Workbook

Sheet Summary
A1: Smart Meal Planner — progress
A2: Counts update from the Tasks tab. Change a task's Status there (pick from the list); add new tasks as new rows.
A4: Status | B4: Tasks | C4: Share
A5: Done | B5: =COUNTIF(Tasks!$D$2:$D$1000,A5) | C5: =IFERROR(B5/$B$10,0)
A6: In review | B6: =COUNTIF(Tasks!$D$2:$D$1000,A6) | C6: =IFERROR(B6/$B$10,0)
A7: In progress | B7: =COUNTIF(Tasks!$D$2:$D$1000,A7) | C7: =IFERROR(B7/$B$10,0)
A8: To do | B8: =COUNTIF(Tasks!$D$2:$D$1000,A8) | C8: =IFERROR(B8/$B$10,0)
A9: Cancelled | B9: =COUNTIF(Tasks!$D$2:$D$1000,A9) | C9: =IFERROR(B9/$B$10,0)
A10: All tasks | B10: =SUM(B5:B9)
A12: Complete (done ÷ tasks not cancelled) | B12: =IFERROR((B5+B6)/(B10-B9),0)
A13: Counts 'In review' as done: finished, awaiting merge.
A15: Area | B15: Done | C15: Open
A16: Design | B16: =COUNTIFS(Tasks!$B$2:$B$1000,A16,Tasks!$D$2:$D$1000,"Done")+COUNTIFS(Tasks!$B$2:$B$1000,A16,Tasks!$D$2:$D$1000,"In review") | C16: =COUNTIFS(Tasks!$B$2:$B$1000,A16,Tasks!$D$2:$D$1000,"To do")+COUNTIFS(Tasks!$B$2:$B$1000,A16,Tasks!$D$2:$D$1000,"In progress")
A17: Docs | B17: =COUNTIFS(Tasks!$B$2:$B$1000,A17,Tasks!$D$2:$D$1000,"Done")+COUNTIFS(Tasks!$B$2:$B$1000,A17,Tasks!$D$2:$D$1000,"In review") | C17: =COUNTIFS(Tasks!$B$2:$B$1000,A17,Tasks!$D$2:$D$1000,"To do")+COUNTIFS(Tasks!$B$2:$B$1000,A17,Tasks!$D$2:$D$1000,"In progress")
A18: Foundation | B18: =COUNTIFS(Tasks!$B$2:$B$1000,A18,Tasks!$D$2:$D$1000,"Done")+COUNTIFS(Tasks!$B$2:$B$1000,A18,Tasks!$D$2:$D$1000,"In review") | C18: =COUNTIFS(Tasks!$B$2:$B$1000,A18,Tasks!$D$2:$D$1000,"To do")+COUNTIFS(Tasks!$B$2:$B$1000,A18,Tasks!$D$2:$D$1000,"In progress")
A19: Grocery data | B19: =COUNTIFS(Tasks!$B$2:$B$1000,A19,Tasks!$D$2:$D$1000,"Done")+COUNTIFS(Tasks!$B$2:$B$1000,A19,Tasks!$D$2:$D$1000,"In review") | C19: =COUNTIFS(Tasks!$B$2:$B$1000,A19,Tasks!$D$2:$D$1000,"To do")+COUNTIFS(Tasks!$B$2:$B$1000,A19,Tasks!$D$2:$D$1000,"In progress")
A20: Grocery list | B20: =COUNTIFS(Tasks!$B$2:$B$1000,A20,Tasks!$D$2:$D$1000,"Done")+COUNTIFS(Tasks!$B$2:$B$1000,A20,Tasks!$D$2:$D$1000,"In review") | C20: =COUNTIFS(Tasks!$B$2:$B$1000,A20,Tasks!$D$2:$D$1000,"To do")+COUNTIFS(Tasks!$B$2:$B$1000,A20,Tasks!$D$2:$D$1000,"In progress")
A21: Offers | B21: =COUNTIFS(Tasks!$B$2:$B$1000,A21,Tasks!$D$2:$D$1000,"Done")+COUNTIFS(Tasks!$B$2:$B$1000,A21,Tasks!$D$2:$D$1000,"In review") | C21: =COUNTIFS(Tasks!$B$2:$B$1000,A21,Tasks!$D$2:$D$1000,"To do")+COUNTIFS(Tasks!$B$2:$B$1000,A21,Tasks!$D$2:$D$1000,"In progress")
A22: Offline | B22: =COUNTIFS(Tasks!$B$2:$B$1000,A22,Tasks!$D$2:$D$1000,"Done")+COUNTIFS(Tasks!$B$2:$B$1000,A22,Tasks!$D$2:$D$1000,"In review") | C22: =COUNTIFS(Tasks!$B$2:$B$1000,A22,Tasks!$D$2:$D$1000,"To do")+COUNTIFS(Tasks!$B$2:$B$1000,A22,Tasks!$D$2:$D$1000,"In progress")
A23: Performance | B23: =COUNTIFS(Tasks!$B$2:$B$1000,A23,Tasks!$D$2:$D$1000,"Done")+COUNTIFS(Tasks!$B$2:$B$1000,A23,Tasks!$D$2:$D$1000,"In review") | C23: =COUNTIFS(Tasks!$B$2:$B$1000,A23,Tasks!$D$2:$D$1000,"To do")+COUNTIFS(Tasks!$B$2:$B$1000,A23,Tasks!$D$2:$D$1000,"In progress")
A24: Planner | B24: =COUNTIFS(Tasks!$B$2:$B$1000,A24,Tasks!$D$2:$D$1000,"Done")+COUNTIFS(Tasks!$B$2:$B$1000,A24,Tasks!$D$2:$D$1000,"In review") | C24: =COUNTIFS(Tasks!$B$2:$B$1000,A24,Tasks!$D$2:$D$1000,"To do")+COUNTIFS(Tasks!$B$2:$B$1000,A24,Tasks!$D$2:$D$1000,"In progress")
A25: Preferences | B25: =COUNTIFS(Tasks!$B$2:$B$1000,A25,Tasks!$D$2:$D$1000,"Done")+COUNTIFS(Tasks!$B$2:$B$1000,A25,Tasks!$D$2:$D$1000,"In review") | C25: =COUNTIFS(Tasks!$B$2:$B$1000,A25,Tasks!$D$2:$D$1000,"To do")+COUNTIFS(Tasks!$B$2:$B$1000,A25,Tasks!$D$2:$D$1000,"In progress")
A26: Quality | B26: =COUNTIFS(Tasks!$B$2:$B$1000,A26,Tasks!$D$2:$D$1000,"Done")+COUNTIFS(Tasks!$B$2:$B$1000,A26,Tasks!$D$2:$D$1000,"In review") | C26: =COUNTIFS(Tasks!$B$2:$B$1000,A26,Tasks!$D$2:$D$1000,"To do")+COUNTIFS(Tasks!$B$2:$B$1000,A26,Tasks!$D$2:$D$1000,"In progress")
A27: Recipes | B27: =COUNTIFS(Tasks!$B$2:$B$1000,A27,Tasks!$D$2:$D$1000,"Done")+COUNTIFS(Tasks!$B$2:$B$1000,A27,Tasks!$D$2:$D$1000,"In review") | C27: =COUNTIFS(Tasks!$B$2:$B$1000,A27,Tasks!$D$2:$D$1000,"To do")+COUNTIFS(Tasks!$B$2:$B$1000,A27,Tasks!$D$2:$D$1000,"In progress")
... A29: Settings | B29: =COUNTIFS(Tasks!$B$2:$B$1000,A29,Tasks!$D$2:$D$1000,"Done")+COUNTIFS(Tasks!$B$2:$B$1000,A29,Tasks!$D$2:$D$1000,"In review") | C29: =COUNTIFS(Tasks!$B$2:$B$1000,A29,Tasks!$D$2:$D$1000,"To do")+COUNTIFS(Tasks!$B$2:$B$1000,A29,Tasks!$D$2:$D$1000,"In progress")

Sheet Tasks
A1: ID | B1: Area | C1: Task | D1: Status | E1: Owner | F1: PR | G1: Done on | H1: Notes
A2: T01 | B2: Foundation | C2: Initial SwiftUI app, project name and README | D2: Done | E2: Claude | F2: #1–#8 | G2: 46300
A3: T02 | B3: Design | C3: Revamp the UI across all screens to match the Figma design | D3: Done | E3: Claude | F3: #9 | G3: 46304
A4: T03 | B4: Design | C4: Branded launch screen and app screenshots in the README | D4: Done | E4: Claude | F4: #10 | G4: 46304
A5: T04 | B5: Preferences | C5: Derive the shopping region from the postcode | D5: Done | E5: Claude | F5: #11 | G5: 46304
A6: T05 | B6: Quality | C6: Fix CI: build the Xcode project | D6: Done | E6: Claude | F6: #12 | G6: 46308
A7: T06 | B7: Quality | C7: Unit tests for every screen, run in CI | D7: Done | E7: Claude | F7: #13, #14 | G7: 46308
A8: T07 | B8: Design | C8: App icon | D8: Done | E8: Claude | F8: #14 | G8: 46308
A9: T08 | B9: Settings | C9: Settings screen: theme and version | D9: Done | E9: Claude | F9: #15 | G9: 46309
A10: T09 | B10: Quality | C10: UI tests and app icon tests | D10: Done | E10: Claude | F10: #15 | G10: 46309
A11: T10 | B11: Quality | C11: Record every test run in the test report Google Sheet | D11: Done | E11: Claude | F11: #16 | G11: 46309
A12: T11 | B12: Release | C12: Merge develop into main (UI revamp, region, tests, CI, test report) | D12: Done | E12: You | F12: #17 | G12: 46310
A13: T12 | B13: Grocery data | C13: Weekly grocery database: each store fetched on its offer day | D13: Done | E13: Claude | F13: #18 | G13: 46310 | H13: SQLite + GitHub Actions; app downloads only when the feed changed
A14: T13 | B14: Grocery data | C14: Supabase table editor to view and edit prices | D14: Done | E14: Claude | F14: #18–#20 | G14: 46310
A15: T14 | B15: Grocery data | C15: Fix Supabase sync rejected as a browser | D15: Done | E15: Claude | F15: #19 | G15: 46310
A16: T15 | B16: Grocery data | C16: Fill an empty Supabase mirror when no store is due | D16: Done | E16: Claude | F16: #20 | G16: 46310
A17: T16 | B17: Offers | C17: Product photos in the database and on offers | D17: Done | E17: Claude | F17: #21 | G17: 46310
A18: T17 | B18: Grocery list | C18: Add-to-list buttons, store filters, editable list tab with totals | D18: Done | E18: Claude | F18: #21 | G18: 46310
A19: T18 | B19: Preferences | C19: Preferences save on the first submit | D19: Done | E19: Claude | F19: #22 | G19: 46314
A20: T19 | B20: Planner | C20: No dish more than once a day or twice a week | D20: Done | E20: Claude | F20: #22 | G20: 46314
A21: T20 | B21: Preferences | C21: Number of people; recipes and groceries scale to it | D21: Done | E21: Claude | F21: #22 | G21: 46314
A22: T21 | B22: Recipes | C22: Prep, cook and total time instead of the step count | D22: Done | E22: Claude | F22: #22 | G22: 46314
A23: T22 | B23: Recipes | C23: YouTube links open in the YouTube app, else Safari | D23: Done | E23: Claude | F23: #22 | G23: 46314
A24: T23 | B24: Offers | C24: Supermarket logos in the store filters | D24: Done | E24: Claude | F24: #22 | G24: 46314
A25: T24 | B25: Settings | C25: Profile: weekly spending and savings against the budget | D25: Done | E25: Claude | F25: #22 | G25: 46314
A26: T25 | B26: Preferences | C26: Stores within 2 km of the postcode | D26: Done | E26: Claude | F26: #22 | G26: 46314
A27: T26 | B27: Settings | C27: Notifications when a supermarket's new offers are in | D27: Done | E27: Claude | F27: #22 | G27: 46314 | H27: Local notifications on each store's offer day
A28: T27 | B28: Recipes | C28: AI-assisted recipe search for the preferences | D28: Done | E28: Claude | F28: #22, #25 | G28: 46315 | H28: Spoonacular + Claude Haiku via a Supabase function
A29: T28 | B29: Docs | C29: API docs and Postman security checks | D29: Done | E29: Claude | F29: #22 | G29: 46314
A30: T29 | B30: Docs | C30: README split into summary, features, design, API and test documents | D30: Done | E30: Claude | F30: #22 | G30: 46314
A31: T30 | B31: Design | C31: Update the Figma screens | D31: Done | E31: Claude | F31: #22 | G31: 46314
A32: T31 | B32: Offers | C32: Albert Heijn offers from Open Prices; add AH Bonus deals yourself | D32: Done | E32: Claude | F32: #23 | G32: 46314
A33: T32 | B33: Grocery data | C33: Fix Dirk/DekaMarkt normal prices (Pepsi −93%) | D33: Done | E33: Claude | F33: #24 | G33: 46315
A34: T33 | B34: Offers | C34: Product photos for every store (refresh the feed) | D34: Done | E34: Claude | G34: 46315 | H34: Re-fetched Jumbo, Dirk, Hoogvliet
A35: T34 | B35: Performance | C35: Fix lag when switching tabs and themes | D35: Done | E35: Claude | F35: #25 | G35: 46315 | H35: Launch hang 2.0 s → 0.4 s
A36: T35 | B36: Recipes | C36: Real recipes with sources: Spoonacular original link and real YouTube videos | D36: Done | E36: Claude | F36: #25 | G36: 46315
A37: T36 | B37: Recipes | C37: Detailed steps; fix recipe page alignment | D37: Done | E37: Claude | F37: #25 | G37: 46315
A38: T37 | B38: Recipes | C38: No built-in sample recipes; on-device AI fallback with recipe-site links | D38: Done | E38: Claude | F38: #25 | G38: 46315
A39: T38 | B39: Offline | C39: Offline shows stored data or 'needs internet', never samples | D39: Done | E39: Claude | F39: #25 | G39: 46315
A40: T39 | B40: Docs | C40: README screenshots updated and every feature explained | D40: Done | E40: Claude | F40: #25 | G40: 46315
...
